Workbook

Sheet ASSUMPTIONS
A1: Revenue Assumptions | B1: Column1 | C1: Column2 | D1: Column3
A2: Fiscal Year | B2: Total Revenue (₹ Cr) | C2: YoY Growth % | D2: Growth Rate Method | F2: Context/Drivers
A3: 2020-21 (A) | B3: 64869 | C3: =5% -> 0.05 | D3: =B3*(1+C3) -> 68112.45 | F3: Initial recovery phase post-COVID lockdowns.
A4: 2021-22 (A) | B4: 129021 | C4: =56.1% -> 0.561 | D4: =B4*(1+C4) -> 201401.78 | F4: Record-high global steel prices and strong demand.
A5: 2022-23 (A) | B5: 129007 | C5: -0.002 | D5: =B5*(1+C5) -> 128748.99 | F5: Price correction and rising energy costs in Europe.
A6: 2023-24 (A) | B6: 136111 | C6: -0.058 | D6: =B6*(1+C6) -> 128216.56 | F6: Global slowdown and margin pressure in UK/Netherlands.
A7: 2024-25 (A) | B7: 142100 | C7: -0.046 | D7: =B7*(1+C7) -> 135563.4 | F7: Decommissioning of UK blast furnaces; focus on India growth.
A9: Cost Structure Assumptions
A10: Fiscal Year | B10: Total Revenue (₹ Cr) | C10: COGS | D10: Gross Margin | E10: Projected Gross Profit | F10: Projected COGS
A11: 2020-21 (A) | B11: 64869 | C11: 18780 | D11: =(B11-C11)/B11 -> 0.71049346 | E11: =B11*D11 -> 46089 | F11: =B11-E11 -> 18780
A12: 2021-22 (A) | B12: 129021 | C12: 37822 | D12: =(B12-C12)/B12 -> 0.70685392 | E12: =B12*D12 -> 91199 | F12: =B12-E12 -> 37822
A13: 2022-23 (A) | B13: 129007 | C13: 51490 | D13: =(B13-C13)/B13 -> 0.60087437 | E13: =B13*D13 -> 77517 | F13: =B13-E13 -> 51490
A14: 2023-24 (A) | B14: 136111 | C14: 53985 | D14: =(B14-C14)/B14 -> 0.60337519 | E14: =B14*D14 -> 82126 | F14: =B14-E14 -> 53985
A15: 2024-25 (A) | B15: 142100 | C15: 54250 | D15: =(B15-C15)/B15 -> 0.6182266 | E15: =B15*D15 -> 87850 | F15: =B15-E15 -> 54250
A17: COGS % of Revenue | B17: Column1 | C17: Column2 | D17: Column3 | E17: Column4
A18: Fiscal Year | B18: Total Revenue (₹ Cr) | C18: COGS | D18: COGS % FORECAST | E18: : COGS % of Revenue(Cost-Focused)
A19: 2020-21 (A) | B19: 64869 | C19: 18780 | D19: =C19/B19 -> 0.28950654 | E19: =B19*D19 -> 18780
A20: 2021-22 (A) | B20: 129021 | C20: 37822 | D20: =C20/B20 -> 0.29314608 | E20: =B20*D20 -> 37822
A21: 2022-23 (A) | B21: 129007 | C21: 51490 | D21: =C21/B21 -> 0.39912563 | E21: =B21*D21 -> 51490
A22: 2023-24 (A) | B22: 136111 | C22: 53985 | D22: =C22/B22 -> 0.39662481 | E22: =B22*D22 -> 53985
A23: 2024-25 (A) | B23: 142100 | C23: 54250 | D23: =C23/B23 -> 0.3817734 | E23: =B23*D23 -> 54250

Sheet Income Statement
A2: Column1 | B2: Column2 | C2: Column3 | D2: Column4 | E2: Column5 | F2: Column6 | G2: Column7
A3: Particulars | C3: FY21 | D3: FY22 | E3: FY23 | F3: FY24 | G3: FY25 (Est)
A4: I. REVENUE
A5: Revenue from Operations | C5: 64869 | D5: 129021 | E5: 129007 | F5: 136111 | G5: 142100
A6: Other Income | C6: 1023 | D6: 871 | E6: 1045 | F6: 1210 | G6: 1350
A7: Total Revenue (A) | C7: =SUM(C5:C6) -> 65892 | D7: =SUM(D5:D6) -> 129892 | E7: =SUM(E5:E6) -> 130052 | F7: =SUM(F5:F6) -> 137321 | G7: =SUM(G5:G6) -> 143450
A9: II. COST OF GOODS SOLD (COGS)
A10: Materials Consumed | C10: 17450 | D10: 33452 | E10: 44120 | F10: 46215 | G10: 47500
A11: Purchases of Stock-in-Trade | C11: 2540 | D11: 6520 | E11: 8910 | F11: 7450 | G11: 7200
A12: Change in Inventory (FG & WIP) | C12: -1210 | D12: -2150 | E12: -1540 | F12: 320 | G12: -450
A13: Total COGS (B) | C13: =SUM(C10:C12) -> 18780 | D13: =SUM(D10:D12) -> 37822 | E13: =SUM(E10:E12) -> 51490 | F13: =SUM(F10:F12) -> 53985 | G13: =SUM(G10:G12) -> 54250
A15: III. GROSS PROFIT (A - B) | C15: =C7-C13 -> 47112 | D15: =D7-D13 -> 92070 | E15: =E7-E13 -> 78562 | F15: =F7-F13 -> 83336 | G15: =G7-G13 -> 89200
A17: IV. OPERATING EXPENSES
A18: Employee Benefit Expense | C18: 5234 | D18: 6051 | E18: 6321 | F18: 6850 | G18: 7100
A19: Depreciation & Amortization | C19: 4320 | D19: 4450 | E19: 4560 | F19: 4820 | G19: 5050
A20: Other Operating Expenses | C20: 18150 | D20: 28150 | E20: 36450 | F20: 39210 | G20: 40500
A21: Total Operating Exp. (D) | C21: =SUM(C18:C20) -> 27704 | D21: =SUM(D18:D20) -> 38651 | E21: =SUM(E18:E20) -> 47331 | F21: =SUM(F18:F20) -> 50880 | G21: =SUM(G18:G20) -> 52650
A23: V. OPERATING PROFIT (EBIT) | C23: =C15-C21 -> 19408 | D23: =D15-D21 -> 53419 | E23: =E15-E21 -> 31231 | F23: =F15-F21 -> 32456 | G23: =G15-G21 -> 36550
A25: Finance Costs (Interest) | C25: 3015 | D25: 2850 | E25: 3210 | F25: 3450 | G25: 3300
A26: Profit/Loss before Exceptional Items | C26: 16393 | D26: 50569 | E26: 28021 | F26: 29406 | G26: 33250
A27: Exceptional Items | C27: -980 | D27: -150 | E27: -1200 | F27: -2500 | G27: -800
A28: VI. PROFIT BEFORE TAX (PBT) | C28: =C26+C27 -> 15413 | D28: =D26+D27 -> 50419 | E28: =E26+E27 -> 26821 | F28: =F26+F27 -> 26906 | G28: =G26+G27 -> 32450
A30: VII. TAX EXPENSE
A31: Current Tax | C31: 4050 | D31: 12450 | E31: 6150 | F31: 6450 | G31: 7800
A32: Deferred Tax | C32: 1120 | D32: 4950 | E32: 1580 | F32: 1210 | G32: 1150
A33: Total Tax Expense | C33: =SUM(C31:C32) -> 5170 | D33: =SUM(D31:D32) -> 17400 | E33: =SUM(E31:E32) -> 7730 | F33: =SUM(F31:F32) -> 7660 | G33: =SUM(G31:G32) -> 8950
A35: VIII. PROFIT AFTER TAX (PAT) | C35: =C28-C33 -> 10243 | D35: =D28-D33 -> 33019 | E35: =E28-E33 -> 19091 | F35: =F28-F33 -> 19246 | G35: =G28-G33 -> 23500
A36: IX. OTHER COMPREHENSIVE INC. (OCI) | C36: 115 | D36: -82 | E36: 145 | F36: 90 | G36: 110
A38: Net Profit | C38: =SUM(C35:C36) -> 10358 | D38: =SUM(D35:D36) -> 32937 | E38: =SUM(E35:E36) -> 19236 | F38: =SUM(F35:F36) -> 19336 | G38: =SUM(G35:G36) -> 23610
A40: Metric | B40: Value | C40: Data Source / Description
A41: Risk-Free Rate ($R_f$) | B41: 0.0666 | C41: Based on the current yield of the India 10-Year Government Bond (G-Sec).
A42: Market Return ($R_m$) | B42: 0.145 | C42: Estimated based on the long-term historical CAGR of the Nifty 50 (approx. 12–15%).
A43: Beta ($\beta$) | B43: 1.44 | C43: Reported volatility relative to the Nifty 50; indicates the stock is more volatile than the market.
A44: Effective Tax Rate | B44: 0.2537 | C44: Latest consolidated effective tax rate for the Indian operations (FY 2024-25).
A46: Cost of Equity ($K_e$) | C46: =B41+B43*(B42-B41) -> 0.179496
A47: K_e = R_f + \beta \times (R_m - R_f)

Sheet Balance sheet
A1: Column1 | B1: Column2 | C1: Column3 | D1: Column4 | E1: Column5 | F1: Column6 | I1: — Retained Earnings
A2: Particulars | B2: FY 2020-21 | C2: FY 2021-22 | D2: FY 2022-23 | E2: FY 2023-24 | F2: FY 2024-25 | I2: Financial Year | J2: Opening Balance | K2: Net Profit (PAT) | L2: Dividends Paid* | M2: Others/Adj. | N2: Closing Balance
A3: EQUITY AND LIABILITIES | I3: 2020–21 (FY21) | J3: 37702 | K3: ='Income Statement'!C38 -> 10358 | L3: -1146 | M3: -49 | N3: =SUM(J3:L3) -> 46914
A4: Equity Share Capital | B4: 1198 | C4: 1221 | D4: 1221 | E4: 1248 | F4: 1247 | I4: 2021–22 (FY22) | J4: 50114 | K4: ='Income Statement'!D38 -> 32937 | L4: -3020 | M4: 6 | N4: =SUM(J4:L4) -> 80031
A5: Other Equity (Attr. to owners) | B5: 71044 | C5: 113222 | D5: 101861 | E5: 88857 | F5: 91105 | I5: 2022–23 (FY23) | J5: 80111 | K5: ='Income Statement'!E38 -> 19236 | L5: -6242 | M5: -223 | N5: =SUM(J5:L5) -> 93105
I6: 2023–24 (FY24) | J6: 89141 | K6: ='Income Statement'!F38 -> 19336 | L6: -4490 | M6: 67 | N6: =SUM(J6:L6) -> 103987
A7: Non-controlling Interests | B7: 1980 | C7: 2655 | D7: 2093 | E7: 2210 | F7: 168 | I7: 2024–25 (FY25) | J7: 100380 | K7: ='Income Statement'!G38 -> 23610 | L7: -4494 | M7: -127 | N7: =SUM(J7:L7) -> 119496
A8: Total Equity | B8: =SUM(B4:B7) -> 74222 | C8: =SUM(C4:C7) -> 117098 | D8: =SUM(D4:D7) -> 105175 | E8: =SUM(E4:E7) -> 92315 | F8: =SUM(F4:F7) -> 92520
A10: Non-Current Liabilities
A11: Financial Liabilities — Borrowings | B11: 68206 | C11: 44764 | D11: 51446 | E11: 58410 | F11: 75492
A12: Lease Liabilities | B12: 5412 | C12: 5696 | D12: 5811 | E12: 6112 | F12: 6324
A13: Other Financial Liabilities | B13: 785 | C13: 990 | D13: 1872 | E13: 1550 | F13: 1680
A14: Provisions & RBO | B14: 2120 | C14: 2540 | D14: 2890 | E14: 3450 | F14: 3120
A15: Deferred Tax Liabilities (Net) | B15: 5120 | C15: 22654 | D15: 22250 | E15: 15320 | F15: 14880
A16: Other Non-Current Liabilities | B16: 1401 | C16: 1306 | D16: 1282 | E16: 1450 | F16: 1510
A17: Total Non-Current Liabilities | B17: =SUM(B11:B16) -> 83044 | C17: =SUM(C11:C16) -> 77950 | D17: =SUM(D11:D16) -> 85551 | E17: =SUM(E11:E16) -> 86292 | F17: =SUM(F11:F16) -> 103006
A19: Current Liabilities
A20: Financial Liabilities — Borrowings | B20: 13634 | C20: 15220 | D20: 18220 | E20: 22110 | F20: 19309
A21: Trade Payables (MSME + Others) | B21: 27526 | C21: 35420 | D21: 38110 | E21: 40220 | F21: 38980
A22: Other Financial & Current Liab. | B22: 46064 | C22: 39757 | D22: 40965 | E22: 32483 | F22: 26575
A23: Total Current Liabilities | B23: =SUM(B20:B22) -> 87224 | C23: =SUM(C20:C22) -> 90397 | D23: =SUM(D20:D22) -> 97295 | E23: =SUM(E20:E22) -> 94813 | F23: =SUM(F20:F22) -> 84864
A25: Total Liabilities | B25: =B17+B23 -> 170268 | C25: =C17+C23 -> 168347 | D25: =D17+D23 -> 182846 | E25: =E17+E23 -> 181105 | F25: =F17+F23 -> 187870
A26: Total Liabilities + Equity | B26: =B8+B25 -> 244490 | C26: =C8+C25 -> 285445 | D26: =D8+D25 -> 288021 | E26: =E8+E25 -> 273420 | F26: =F8+F25 -> 280390
A28: ASSETS | B28: 2021 | C28: 2022 | D28: 2023 | E28: 2024 | F28: 2025
A29: Non-Current Assets
A30: Property, Plant & Equipment | B30: 105208 | C30: 116166 | D30: 118697 | E30: 121120 | F30: 125215
A31: Capital Work-in-Progress | B31: 19120 | C31: 21228 | D31: 30308 | E31: 32450 | F31: 36948
A32: Right-of-Use Assets | B32: 8245 | C32: 8338 | D32: 9223 | E32: 9880 | F32: 10210
A33: Goodwill | B33: 4210 | C33: 4311 | D33: 5602 | E33: 1196 | F33: 1196
A34: Other Intangible Assets | B34: 3920 | C34: 4472 | D34: 13101 | E34: 14210 | F34: 15450
A35: Financial Assets (Investments) | B35: 3120 | C35: 2962 | D35: 3233 | E35: 3550 | F35: 3880
A36: Other Non-Current Assets | B36: 38874 | C36: 35411 | D36: 21192 | E36: 20464 | F36: 14168
A37: Total Non-Current Assets | B37: =SUM(B30:B36) -> 182697 | C37: =SUM(C30:C36) -> 192888 | D37: =SUM(D30:D36) -> 201356 | E37: =SUM(E30:E36) -> 202870 | F37: =SUM(F30:F36) -> 207067
A39: Current Assets
A40: Inventories | B40: 28278 | C40: 48824 | D40: 54415 | E40: 49210 | F40: 50490
A41: Trade Receivables | B41: 9530 | C41: 12246 | D41: 8257 | E41: 7650 | F41: 7810
A42: Cash & Cash Equivalents | B42: 5782 | C42: 15605 | D42: 12130 | E42: 6240 | F42: 12222
A43: Other Bank Balances | B43: 7240 | C43: 294 | D43: 1227 | E43: 1110 | F43: 2120
A44: Other Current Assets | B44: 10963 | C44: 15588 | D44: 10636 | E44: 6340 | F44: -319
A45: Total Current Assets | B45: =SUM(B40:B44) -> 61793 | C45: =SUM(C40:C44) -> 92557 | D45: =SUM(D40:D44) -> 86665 | E45: =SUM(E40:E44) -> 70550 | F45: =SUM(F40:F44) -> 72323
...

Sheet Cashflow Statement
A1: Integrated 3-Statement Financial Model
A3: Particulars | B3: Note | C3: FY 2024-25 (A) | D3: FY 2023-24 (A) | E3: FY 2022-23 | F3: FY 2021-22 | G3: FY 2020-21
A4: Cash Flow from Operating Activities | I4: Operating cashflow | J4: 10122 | K4: -10604 | L4: 16913 | M4: 52223 | N4: 13858
A5: Net Profit before taxes (incl. Exceptional) | C5: 10122 | D5: -10604 | E5: 16913 | F5: 52223 | G5: 13858 | I5: Capex | J5: -15671 | K5: -16244 | L5: -18207 | M5: -10522 | N5: -6975
A6: Adjustments for: | I6: Balance | J6: =SUM(J4:J5) -> -5549 | K6: =SUM(K4:K5) -> -26848 | L6: =SUM(L4:L5) -> -1294 | M6: =SUM(M4:M5) -> 41701 | N6: =SUM(N4:N5) -> 6883
A7: * Depreciation and Amortisation | C7: 10421 | D7: 9882 | E7: 9335 | F7: 9101 | G7: 9234
A8: * Interest Expense / Finance Costs | C8: 7341 | D8: 7508 | E8: 6299 | F8: 5463 | G8: 7607
A9: * Interest / Dividend Income | C9: -1540 | D9: -1837 | E9: -1021 | F9: -854 | G9: -722
A10: * Other Non-Cash Items / Provisions | C10: 1245 | D10: 11215 | E10: 845 | F10: 652 | G10: 4210
A11: Operating Profit before Working Capital | C11: =SUM(C5:C10) -> 27589 | D11: =SUM(D5:D10) -> 16164 | E11: =SUM(E5:E10) -> 32371 | F11: =SUM(F5:F10) -> 66585 | G11: =SUM(G5:G10) -> 34187
A12: Adjustments for Working Capital:
A13: * (Inc)/Dec in Trade Receivables | C13: 504 | D13: -1520 | E13: -1230 | F13: -2345 | G13: 1234
A14: * (Inc)/Dec in Inventories | C14: 2130 | D14: -3240 | E14: -4560 | F14: -11432 | G14: 6543
A15: * Inc/(Dec) in Trade Payables | C15: -1240 | D15: 10240 | E15: -3210 | F15: -2120 | G15: 4512
A16: Cash Generated from Operations | C16: =SUM(C11:C15) -> 28983 | D16: =SUM(D11:D15) -> 21644 | E16: =SUM(E11:E15) -> 23371 | F16: =SUM(F11:F15) -> 50688 | G16: =SUM(G11:G15) -> 46476
A17: Less: Income Tax Paid | C17: -5471 | D17: -1343 | E17: -1688 | F17: -6307 | G17: -2155
A18: Net Cash from Operating Activities (A) | C18: =SUM(C16:C17) -> 23512 | D18: =SUM(D16:D17) -> 20301 | E18: =SUM(E16:E17) -> 21683 | F18: =SUM(F16:F17) -> 44381 | G18: =SUM(G16:G17) -> 44321
A19: --- | C19: --- | D19: --- | E19: --- | F19: --- | G19: ---
A20: Cash Flow from Investing Activities
A21: Purchase of Fixed Assets (CapEx) | C21: -15671 | D21: -16244 | E21: -18207 | F21: -10522 | G21: -6975
A22: Sale of Fixed Assets / Investments | C22: 450 | D22: 320 | E22: 150 | F22: 254 | G22: 4560
A23: Interest & Dividend Received | C23: 1048 | D23: 1673 | E23: 921 | F23: 682 | G23: 530
A24: Other Investing Items (Net) | C24: - | D24: - | E24: -1544 | F24: -1295 | G24: -
A25: Net Cash from Investing Activities (B) | C25: =SUM(C21:C24) -> -14173 | D25: =SUM(D21:D24) -> -14251 | E25: =SUM(E21:E24) -> -18680 | F25: =SUM(F21:F24) -> -10881 | G25: =SUM(G21:G24) -> -1885
A26: --- | C26: --- | D26: --- | E26: --- | F26: --- | G26: ---
A27: Cash Flow from Financing Activities
A28: Proceeds from Issue of Shares / NCDs | C28: 3000 | D28: - | E28: - | F28: - | G28: -
A29: Net Borrowings / (Repayment) | C29: -2150 | D29: -3589 | E29: 1340 | F29: -17450 | G29: -26450
A30: Dividend Paid | C30: -4492 | D30: -4492 | E30: -6211 | F30: -3021 | G30: -1154
A31: Interest Paid | C31: -3360 | D31: -3016 | E31: -2110 | F31: -2930 | G31: -6534
A32: Net Cash from Financing Activities (C) | C32: =SUM(C28:C31) -> -7002 | D32: =SUM(D28:D31) -> -11097 | E32: =SUM(E28:E31) -> -6981 | F32: =SUM(F28:F31) -> -23401 | G32: =SUM(G28:G31) -> -34138
A33: --- | C33: --- | D33: --- | E33: --- | F33: --- | G33: ---
A34: Net Increase/Decrease in Cash (A+B+C) | C34: =C18+C25+C32 -> 2337 | D34: =D18+D25+D32 -> -5047 | E34: =E18+E25+E32 -> -3978 | F34: =F18+F25+F32 -> 10099 | G34: =G18+G25+G32 -> 8298
A35: Add: Opening Cash & Equivalents | C35: 9698 | D35: 14745 | E35: 18724 | F35: 8624 | G35: 326
A36: Adjustments/Exchange Diff. | C36: 187 | D36: - | E36: - | F36: - | G36: -
A37: Closing Cash & Cash Equivalents | C37: 12222 | D37: 9698 | E37: 14746 | F37: 18724 | G37: 8624
A47: Note | B47: Rs(2024-25)
A48: Average Inventory | B48: -975
B52: 45.51
B53: 18.72
...

Sheet PP&E Schedule
A1: Asset ID | B1: Description | C1: Cost (Opening) | D1: Additions | E1: Disposals/ Adj | F1: Cost (Closing) | G1: Accum. Dep (Opening) | H1: Depreciation(Salvage value) | I1: Accum. Dep (Closing) | J1: Net Book Value (NBV) | K1: Useful Life (Years)
A2: FY 2020-21 | B2: Total PP&E | C2: 192442 | D2: 7842 | E2: -4321 | F2: =SUM(C2:E2) -> 195963 | G2: 79540 | H2: 9234 | I2: 88774 | J2: =F2-I2 -> 107189 | K2: --
A3: AST-01 | B3: Land & Buildings | C3: 32450 | D3: 450 | E3: -120 | F3: =SUM(C3:E3) -> 32780 | G3: 5120 | H3: 850 | I3: 5970 | J3: =F3-I3 -> 26810 | K3: 30–60
A4: AST-02 | B4: Plant & Mach. | C4: 151200 | D4: 6800 | E4: -3950 | F4: =SUM(C4:E4) -> 154050 | G4: 68400 | H4: 7800 | I4: 76200 | J4: =F4-I4 -> 77850 | K4: 15–40
A5: AST-03 | B5: Others (Misc) | C5: 11792 | D5: 592 | E5: -251 | F5: 12133 | G5: 6020 | H5: 584 | I5: 6604 | J5: =F5-I5 -> 5529 | K5: 3–10
J6: =F6-I6 -> 0
A7: FY 2021-22 | B7: Total PP&E | C7: 198963 | D7: 10522 | E7: -3115 | F7: =SUM(C7:E7) -> 206370 | G7: 88774 | H7: 9101 | I7: 97875 | J7: =F7-I7 -> 108495 | K7: --
A8: AST-01 | B8: Land & Buildings | C8: 32780 | D8: 1120 | E8: -45 | F8: =SUM(C8:E8) -> 33855 | G8: 5970 | H8: 890 | I8: 6860 | J8: =F8-I8 -> 26995 | K8: 30–60
A9: AST-02 | B9: Plant & Mach. | C9: 154050 | D9: 8950 | E9: -2800 | F9: =SUM(C9:E9) -> 160200 | G9: 76200 | H9: 7650 | I9: 83850 | J9: =F9-I9 -> 76350 | K9: 15–40
A10: AST-03 | B10: Others (Misc) | C10: 12133 | D10: 452 | E10: -270 | F10: =SUM(C10:E10) -> 12315 | G10: 6604 | H10: 561 | I10: 7165 | J10: =F10-I10 -> 5150 | K10: 3–10
J11: =F11-I11 -> 0
A12: FY 2022-23 | B12: Total PP&E | C12: 206370 | D12: 14142 | E12: -5680 | F12: =SUM(C12:E12) -> 214832 | G12: 97875 | H12: 9335 | I12: 107210 | J12: =F12-I12 -> 107622 | K12: --
A13: AST-01 | B13: Land & Buildings | C13: 33855 | D13: 2100 | E13: -110 | F13: =SUM(C13:E13) -> 35845 | G13: 6860 | H13: 920 | I13: 7780 | J13: =F13-I13 -> 28065 | K13: 30–60
A14: AST-02 | B14: Plant & Mach. | C14: 163200 | D14: 11200 | E14: -5200 | F14: =SUM(C14:E14) -> 169200 | G14: 83850 | H14: 7850 | I14: 91700 | J14: =F14-I14 -> 77500 | K14: 15–40
A15: AST-03 | B15: Others (Misc) | C15: 12315 | D15: 842 | E15: -370 | F15: =SUM(C15:E15) -> 12787 | G15: 7165 | H15: 565 | I15: 7730 | J15: =F15-I15 -> 5057 | K15: 3–10
J16: =F16-I16 -> 0
A17: FY 2023-24 | B17: Total PP&E | C17: 214832 | D17: 18500 | E17: -8250 | F17: =SUM(C17:E17) -> 225082 | G17: 107210 | H17: 9510 | I17: 116720 | J17: =F17-I17 -> 108362 | K17: --
A18: AST-01 | B18: Land & Buildings | C18: 35845 | D18: 3450 | E18: -1200 | F18: =SUM(C18:E18) -> 38095 | G18: 7780 | H18: 1150 | I18: 8930 | J18: =F18-I18 -> 29165 | K18: 30–60
A19: AST-02 | B19: Plant & Mach. | C19: 166200 | D19: 13850 | E19: -6500 | F19: =SUM(C19:E19) -> 173550 | G19: 91700 | H19: 7800 | I19: 99500 | J19: =F19-I19 -> 74050 | K19: 15–40
A20: AST-03 | B20: Others (Misc) | C20: 12787 | D20: 1200 | E20: -550 | F20: =SUM(C20:E20) -> 13437 | G20: 7730 | H20: 560 | I20: 8290 | J20: =F20-I20 -> 5147 | K20: 3–10
J21: =F21-I21 -> 0
A22: FY 2024-25 | B22: Total PP&E | C22: 225082 | D22: 16120 | E22: -10580 | F22: =SUM(C22:E22) -> 230622 | G22: 116720 | H22: 9680 | I22: 126400 | J22: =F22-I22 -> 104222 | K22: --
A23: AST-01 | B23: Land & Buildings | C23: 38095 | D23: 4200 | E23: -2100 | F23: =SUM(C23:E23) -> 40195 | G23: 8930 | H23: 1250 | I23: 10180 | J23: =F23-I23 -> 30015 | K23: 30–60
A24: AST-02 | B24: Plant & Mach. | C24: 173550 | D24: 10800 | E24: -8100 | F24: =SUM(C24:E24) -> 176250 | G24: 99500 | H24: 7850 | I24: 107350 | J24: =F24-I24 -> 68900 | K24: 15–40
A25: AST-03 | B25: Others (Misc) | C25: 13437 | D25: 1120 | E25: -380 | F25: =SUM(C25:E25) -> 14177 | G25: 8290 | H25: 580 | I25: 8870 | J25: =F25-I25 -> 5307 | K25: 3–10
C26: =SUM(Table1[Cost (Opening)]) -> 2081378 | G26: =SUM(Table1[Accum. Dep (Opening)]) -> 980238

Sheet Debt Schedule
A1: Fiscal Year | B1: Opening Balance | C1: New Loans (Proceeds) | D1: Repayments | E1: Closing Balance | F1: Interest % (Avg) | G1: Interest Expense
A2: FY 2020-21 | B2: 116328 | C2: 15487 | D2: 43314 | E2: =B2+C2-D2 -> 88501 | F2: 0.074 | G2: =(B2+E2)/2*F2 -> 7578.673
A3: FY 2021-22 | B3: 88501 | C3: 11212 | D3: 24152 | E3: =B3+C3-D3 -> 75561 | F3: 0.067 | G3: =(B3+E3)/2*F3 -> 5496.077
A4: FY 2022-23 | B4: 75561 | C4: 30145 | D4: 20813 | E4: =B4+C4-D4 -> 84893 | F4: 0.079 | G4: =(B4+E4)/2*F4 -> 6337.933
A5: FY 2023-24 | B5: 84893 | C5: 18050 | D5: 15861 | E5: =B5+C5-D5 -> 87082 | F5: 0.087 | G5: =(B5+E5)/2*F5 -> 7480.9125
A6: FY 2024-25 | B6: 87082 | C6: 18719 | D6: 11000 | E6: =B6+C6-D6 -> 94801 | F6: 0.081 | G6: =(B6+E6)/2*F6 -> 7366.2615

Sheet Working Capital Schedule
A1: Cash Conversion Cycle (CCC) | B1: FY21 | C1: FY22 | D1: FY23 | E1: FY24 | F1: FY25 (Est) | H1: Particulars | I1: FY21 | J1: FY22 | K1: FY23 | L1: FY24 | M1: FY25 (Est)
A2: DSO (Days Sales Outstanding) = Accounts Receivable/(Revenue/Days) | B2: ='Balance sheet'!B41/'Income Statement'!C5*365 -> 53.622686 | C2: ='Balance sheet'!C41/'Income Statement'!D5*365 -> 34.643895 | D2: ='Balance sheet'!D41/'Income Statement'!E5*365 -> 23.361562 | E2: ='Balance sheet'!E41/'Income Statement'!F5*365 -> 20.514507 | F2: ='Balance sheet'!F41/'Income Statement'!G5*365 -> 20.060873 | H2: Current Assets
A3: DIO (Days Inventory Outstanding)} = Inventory/(COGS/Days) | B3: ='Balance sheet'!B40/'Income Statement'!C13*365 -> 549.59904 | C3: ='Balance sheet'!C40/'Income Statement'!D13*365 -> 471.17445 | D3: ='Balance sheet'!D40/'Income Statement'!E13*365 -> 385.73461 | E3: ='Balance sheet'!E40/'Income Statement'!F13*365 -> 332.71557 | F3: ='Balance sheet'!F40/'Income Statement'!G13*365 -> 339.7023 | H3: Inventories | I3: 28278 | J3: 48824 | K3: 54415 | L3: 49210 | M3: 50490
A4: DPO (Days Payables Outstanding)} = as calculated above | B4: ='Balance sheet'!B21/'Income Statement'!C13*365 -> 534.98349 | C4: ='Balance sheet'!C21/'Income Statement'!D13*365 -> 341.81958 | D4: ='Balance sheet'!D21/'Income Statement'!E13*365 -> 270.15246 | E4: ='Balance sheet'!E21/'Income Statement'!F13*365 -> 271.93294 | F4: ='Balance sheet'!F21/'Income Statement'!G13*365 -> 262.26175 | H4: Trade Receivables | I4: 9530 | J4: 12246 | K4: 8257 | L4: 7650 | M4: 7810
A5: CCC=DSO+DIO−DPO | B5: =B2+B3-B4 -> 68.238234 | C5: =C2+C3-C4 -> 163.99877 | D5: =D2+D3-D4 -> 138.94371 | E5: =E2+E3-E4 -> 81.297131 | F5: =F2+F3-F4 -> 97.501426 | H5: Cash & Cash Equivalents | I5: 5782 | J5: 15605 | K5: 12130 | L5: 6240 | M5: 12222
H6: Other Bank Balances | I6: 7240 | J6: 294 | K6: 1227 | L6: 1110 | M6: 2120
A7: Assumption | B7: FY21 | C7: FY22 | D7: FY23 | E7: FY24 | F7: FY25 (Est) | H7: Other Current Assets | I7: 10963 | J7: 15588 | K7: 10636 | L7: 6340 | M7: -319
A8: Trade Receivables | B8: =B2/365*'Income Statement'!C5 -> 9530 | C8: =C2/365*'Income Statement'!D5 -> 12246 | D8: =D2/365*'Income Statement'!E5 -> 8257 | E8: =E2/365*'Income Statement'!F5 -> 7650 | F8: =F2/365*'Income Statement'!G5 -> 7810 | H8: Total Current Assets | I8: =SUM(I3:I7) -> 61793 | J8: =SUM(J3:J7) -> 92557 | K8: =SUM(K3:K7) -> 86665 | L8: =SUM(L3:L7) -> 70550 | M8: =SUM(M3:M7) -> 72323
A9: Inventory | B9: =B3/365*'Income Statement'!C13 -> 28278 | C9: =C3/365*'Income Statement'!D13 -> 48824 | D9: =D3/365*'Income Statement'!E13 -> 54415 | E9: =E3/365*'Income Statement'!F13 -> 49210 | F9: =F3/365*'Income Statement'!G13 -> 50490
A10: Trade Payables | B10: ='Balance sheet'!B21/'Income Statement'!C13*365 -> 534.98349 | C10: ='Balance sheet'!C21/'Income Statement'!D13*365 -> 341.81958 | D10: ='Balance sheet'!D21/'Income Statement'!E13*365 -> 270.15246 | E10: ='Balance sheet'!E21/'Income Statement'!F13*365 -> 271.93294 | F10: ='Balance sheet'!F21/'Income Statement'!G13*365 -> 262.26175 | H10: Current Liabilities
H11: Financial Liabilities — Borrowings | I11: 13634 | J11: 15220 | K11: 18220 | L11: 22110 | M11: 19309
H12: Trade Payables (MSME + Others) | I12: 27526 | J12: 35420 | K12: 38110 | L12: 40220 | M12: 38980
H13: Other Financial & Current Liab. | I13: 46064 | J13: 39757 | K13: 40965 | L13: 32483 | M13: 26575
H14: Total Current Liabilities | I14: =SUM(I11:I13) -> 87224 | J14: =SUM(J11:J13) -> 90397 | K14: =SUM(K11:K13) -> 97295 | L14: =SUM(L11:L13) -> 94813 | M14: =SUM(M11:M13) -> 84864
H16: WC | I16: =I8-I14 -> -25431 | J16: =J8-J14 -> 2160 | K16: =K8-K14 -> -10630 | L16: =L8-L14 -> -24263 | M16: =M8-M14 -> -12541

Sheet Financial ratios
A1: I. Margin Profitability | B1: FY21 | C1: FY22 | D1: FY23 | E1: FY24 | F1: FY25 (Est)
A2: Gross margin Revenue | B2: ='Income Statement'!C5-'Income Statement'!C13/'Income Statement'!C5 -> 64868.71 | C2: ='Income Statement'!D5-'Income Statement'!D13/'Income Statement'!D5 -> 129020.71 | D2: ='Income Statement'!E5-'Income Statement'!E13/'Income Statement'!E5 -> 129006.6 | E2: ='Income Statement'!F5-'Income Statement'!F13/'Income Statement'!F5 -> 136110.6 | F2: ='Income Statement'!G5-'Income Statement'!G13/'Income Statement'!G5 -> 142099.62
A3: EBITDA Margin | B3: ='Income Statement'!C23/'Income Statement'!C5*100 -> 29.918759 | C3: ='Income Statement'!D23/'Income Statement'!D5*100 -> 41.403337 | D3: ='Income Statement'!E23/'Income Statement'!E5*100 -> 24.208764 | E3: ='Income Statement'!F23/'Income Statement'!F5*100 -> 23.845244 | F3: ='Income Statement'!G23/'Income Statement'!G5*100 -> 25.721323
A4: Net Margin | B4: ='Income Statement'!C38/'Income Statement'!C7*100 -> 15.719662 | C4: ='Income Statement'!D38/'Income Statement'!D7*100 -> 25.35722 | D4: ='Income Statement'!E38/'Income Statement'!E7*100 -> 14.791007 | E4: ='Income Statement'!F38/'Income Statement'!F7*100 -> 14.080876 | F4: ='Income Statement'!G38/'Income Statement'!G7*100 -> 16.458696
A7: Column1 | B7: Column2 | C7: Column3 | D7: Column4 | E7: Column5 | F7: Column6
A8: II. Return Profitability
A9: 1. Return on Equity (ROE) | B9: ='Income Statement'!C38/'Balance sheet'!B4 -> 8.6460768 | C9: ='Income Statement'!D38/'Balance sheet'!C4 -> 26.97543 | D9: ='Income Statement'!E38/'Balance sheet'!D4 -> 15.7543 | E9: ='Income Statement'!F38/'Balance sheet'!E4 -> 15.49359 | F9: ='Income Statement'!G38/'Balance sheet'!F4 -> 18.93344
A10: 2. Return on Assets (ROA) | B10: ='Income Statement'!C38/'Balance sheet'!B47 -> 0.042365741 | C10: ='Income Statement'!D38/'Balance sheet'!C47 -> 0.11538825 | D10: ='Income Statement'!E38/'Balance sheet'!D47 -> 0.066786797 | E10: ='Income Statement'!F38/'Balance sheet'!E47 -> 0.07071904 | F10: ='Income Statement'!G38/'Balance sheet'!F47 -> 0.08450553
A11: 3. Return on Capital Employed (ROCE) | B11: ='Income Statement'!C23/('Balance sheet'!B47-'Balance sheet'!B23) -> 0.12340875 | C11: ='Income Statement'!D23/('Balance sheet'!C47-'Balance sheet'!C23) -> 0.27387617 | D11: ='Income Statement'!E23/('Balance sheet'!D47-'Balance sheet'!D23) -> 0.16374799 | E11: ='Income Statement'!F23/('Balance sheet'!E47-'Balance sheet'!E23) -> 0.1817174 | F11: ='Income Statement'!G23/('Balance sheet'!F47-'Balance sheet'!F23) -> 0.18789262
A13: 1. Liquidity Ratios
A15: Current Ratio | B15: ='Balance sheet'!B45/'Balance sheet'!B23 -> 0.70844034 | C15: ='Balance sheet'!C45/'Balance sheet'!C23 -> 1.0238946 | D15: ='Balance sheet'!D45/'Balance sheet'!D23 -> 0.89074464 | E15: ='Balance sheet'!E45/'Balance sheet'!E23 -> 0.74409627 | F15: ='Balance sheet'!F45/'Balance sheet'!F23 -> 0.85222238
A16: Quick Ratio | B16: =('Balance sheet'!B45-'Balance sheet'!B40)/'Balance sheet'!B23 -> 0.38424058 | C16: =('Balance sheet'!C45-'Balance sheet'!C40)/'Balance sheet'!C23 -> 0.48378818 | D16: =('Balance sheet'!D45-'Balance sheet'!D40)/'Balance sheet'!D23 -> 0.33146616 | E16: =('Balance sheet'!E45-'Balance sheet'!E40)/'Balance sheet'!E23 -> 0.22507462 | F16: =('Balance sheet'!F45-'Balance sheet'!F40)/'Balance sheet'!F23 -> 0.25727046
A18: 2. Leverage & Efficiency Ratios
A20: Column1 | B20: ='Balance sheet'!B25/'Balance sheet'!B4 -> 142.12688 | C20: ='Balance sheet'!C25/'Balance sheet'!C4 -> 137.87633 | D20: ='Balance sheet'!D25/'Balance sheet'!D4 -> 149.75102 | E20: ='Balance sheet'!E25/'Balance sheet'!E4 -> 145.11619 | F20: ='Balance sheet'!F25/'Balance sheet'!F4 -> 150.65758
A21: Debt-to-Equity Ratio (D/E) | B21: ='Income Statement'!C13/'Balance sheet'!B40 -> 0.66412052 | C21: ='Income Statement'!D13/'Balance sheet'!C40 -> 0.77466 | D21: ='Income Statement'!E13/'Balance sheet'!D40 -> 0.94624644 | E21: ='Income Statement'!F13/'Balance sheet'!E40 -> 1.0970331 | F21: ='Income Statement'!G13/'Balance sheet'!F40 -> 1.0744702
A22: Inventory Turnover Ratio
